Traceback (most recent call last):
  File "C:\Users\vanlance\AppData\Local\Programs\Python\Python35\lib\site-packages\urllib3\connection.py", line 171, in _new_conn
    (self._dns_host, self.port), self.timeout, **extra_kw)
  File "C:\Users\vanlance\AppData\Local\Programs\Python\Python35\lib\site-packages\urllib3\util\connection.py", line 56, in create_connection
    for res in socket.getaddrinfo(host, port, family, socket.SOCK_STREAM):
  File "C:\Users\vanlance\AppData\Local\Programs\Python\Python35\lib\socket.py", line 732, in getaddrinfo
    for res in _socket.getaddrinfo(host, port, family, type, proto, flags):
socket.gaierror: [Errno 11001] getaddrinfo failed

During handling of the above exception, another exception occurred:

Traceback (most recent call last):
  File "C:\Users\vanlance\AppData\Local\Programs\Python\Python35\lib\site-packages\urllib3\connectionpool.py", line 600, in urlopen
    chunked=chunked)
  File "C:\Users\vanlance\AppData\Local\Programs\Python\Python35\lib\site-packages\urllib3\connectionpool.py", line 343, in _make_request
    self._validate_conn(conn)
  File "C:\Users\vanlance\AppData\Local\Programs\Python\Python35\lib\site-packages\urllib3\connectionpool.py", line 849, in _validate_conn
    conn.connect()
  File "C:\Users\vanlance\AppData\Local\Programs\Python\Python35\lib\site-packages\urllib3\connection.py", line 314, in connect
    conn = self._new_conn()
  File "C:\Users\vanlance\AppData\Local\Programs\Python\Python35\lib\site-packages\urllib3\connection.py", line 180, in _new_conn
    self, "Failed to establish a new connection: %s" % e)
urllib3.exceptions.NewConnectionError: <urllib3.connection.VerifiedHTTPSConnection object at 0x00000168E441B048>: Failed to establish a new connection: [Errno 11001] getaddrinfo failed

During handling of the above exception, another exception occurred:

Traceback (most recent call last):
  File "C:\Users\vanlance\AppData\Local\Programs\Python\Python35\lib\site-packages\requests\adapters.py", line 445, in send
    timeout=timeout
  File "C:\Users\vanlance\AppData\Local\Programs\Python\Python35\lib\site-packages\urllib3\connectionpool.py", line 638, in urlopen
    _stacktrace=sys.exc_info()[2])
  File "C:\Users\vanlance\AppData\Local\Programs\Python\Python35\lib\site-packages\urllib3\util\retry.py", line 398, in increment
    raise MaxRetryError(_pool, url, error or ResponseError(cause))
urllib3.exceptions.MaxRetryError: HTTPSConnectionPool(host='api.huobi.br.com', port=443): Max retries exceeded with url: /market/depth?type=percent10&symbol=eosusdt (Caused by NewConnectionError('<urllib3.connection.VerifiedHTTPSConnection object at 0x00000168E441B048>: Failed to establish a new connection: [Errno 11001] getaddrinfo failed',))

During handling of the above exception, another exception occurred:

Traceback (most recent call last):
  File "F:\mygit\python\exchange_dj\index\api\api.py", line 43, in inn
    data = fun(*args,**kw)
  File "F:\mygit\python\exchange_dj\index\api\hb\hb_api.py", line 49, in depth
    data = get_depth(symbol)
  File "F:\mygit\python\exchange_dj\index\api\hb\HuobiServices.py", line 48, in get_depth
    return http_get_request(url, params)
  File "F:\mygit\python\exchange_dj\index\api\hb\Utils.py", line 45, in http_get_request
    response = requests.get(url, postdata, headers=headers, timeout=10)
  File "C:\Users\vanlance\AppData\Local\Programs\Python\Python35\lib\site-packages\requests\api.py", line 72, in get
    return request('get', url, params=params, **kwargs)
  File "C:\Users\vanlance\AppData\Local\Programs\Python\Python35\lib\site-packages\requests\api.py", line 58, in request
    return session.request(method=method, url=url, **kwargs)
  File "C:\Users\vanlance\AppData\Local\Programs\Python\Python35\lib\site-packages\requests\sessions.py", line 512, in request
    resp = self.send(prep, **send_kwargs)
  File "C:\Users\vanlance\AppData\Local\Programs\Python\Python35\lib\site-packages\requests\sessions.py", line 622, in send
    r = adapter.send(request, **kwargs)
  File "C:\Users\vanlance\AppData\Local\Programs\Python\Python35\lib\site-packages\requests\adapters.py", line 513, in send
    raise ConnectionError(e, request=request)
requests.exceptions.ConnectionError: HTTPSConnectionPool(host='api.huobi.br.com', port=443): Max retries exceeded with url: /market/depth?type=percent10&symbol=eosusdt (Caused by NewConnectionError('<urllib3.connection.VerifiedHTTPSConnection object at 0x00000168E441B048>: Failed to establish a new connection: [Errno 11001] getaddrinfo failed',))
